Workbook

Sheet SC1
A1: reduction | B1: $SC_{0}$ | C1: $C_{1}(_x000C_rac{1}{3}, 3)$ | D1: $C_{1}(0, 3)$ | E1: $C_{1}(0, 2)$ | F1: $C_{1}(0, 1.5)$ | G1: $C_{1}(0, 1.25)$ | H1: $C_{2}(2)$ | I1: $C_{2}(1)$ | J1: $C_{3}(0,2,2)$ | K1: $C_{3}(0,2,1)$
A2: 0 | B2: 7.8350819e-11 | C2: 7.8350819e-11 | D2: 7.8350819e-11 | E2: 7.8350819e-11 | F2: 7.8350819e-11 | G2: 7.8350819e-11 | H2: 7.8350819e-11 | I2: 7.8350819e-11 | J2: 7.8350819e-11 | K2: 7.8350819e-11
A3: 0.01 | B3: 0.14259987 | C3: 0.14759023 | D3: 0.14259987 | E3: 0.14259987 | F3: 0.14259987 | G3: 0.14259987 | H3: 0.14259987 | I3: 0.18324301 | J3: 0.14259987 | K3: 0.18324301
A4: 0.02 | B4: 0.30223134 | C4: 0.31053726 | D4: 0.30223134 | E4: 0.30223134 | F4: 0.30223134 | G4: 0.30223134 | H4: 0.30223134 | I4: 0.38515054 | J4: 0.30223134 | K4: 0.38515054
A5: 0.03 | B5: 0.46580589 | C5: 0.47508545 | D5: 0.46580589 | E5: 0.46580589 | F5: 0.46580589 | G5: 0.46580589 | H5: 0.46580589 | I5: 0.59020794 | J5: 0.46580589 | K5: 0.59020794
A6: 0.04 | B6: 0.63026086 | C6: 0.64000099 | D6: 0.63026086 | E6: 0.63026086 | F6: 0.63026086 | G6: 0.63026086 | H6: 0.63026086 | I6: 0.79598456 | J6: 0.63026086 | K6: 0.79598456
A7: 0.05 | B7: 0.7950501 | C7: 0.80505815 | D7: 0.7950501 | E7: 0.7950501 | F7: 0.7950501 | G7: 0.7950501 | H7: 0.7950501 | I7: 1.0020374 | J7: 0.7950501 | K7: 1.0020374
A8: 0.06 | B8: 0.96000148 | C8: 0.97068725 | D8: 0.96000148 | E8: 0.96000148 | F8: 0.96000148 | G8: 0.96000148 | H8: 0.96000148 | I8: 1.2082252 | J8: 0.96000148 | K8: 1.2082252
A9: 0.07 | B9: 1.1250437 | C9: 1.1389736 | D9: 1.1250437 | E9: 1.1250437 | F9: 1.1250437 | G9: 1.1250437 | H9: 1.1250437 | I9: 1.4144888 | J9: 1.1250437 | K9: 1.4144888
A10: 0.08 | B10: 1.2901419 | C10: 1.3092061 | D10: 1.2901419 | E10: 1.2901419 | F10: 1.2901419 | G10: 1.2901419 | H10: 1.2901419 | I10: 1.6213289 | J10: 1.2901419 | K10: 1.6213289
A11: 0.09 | B11: 1.4560309 | C11: 1.4815671 | D11: 1.4560309 | E11: 1.4560309 | F11: 1.4560309 | G11: 1.4560309 | H11: 1.4560309 | I11: 1.8303375 | J11: 1.4560309 | K11: 1.8303375
A12: 0.1 | B12: 1.6239268 | C12: 1.6559359 | D12: 1.6239268 | E12: 1.6239268 | F12: 1.6239268 | G12: 1.6239268 | H12: 1.6239268 | I12: 2.0410048 | J12: 1.6239268 | K12: 2.0410048
A13: 0.11 | B13: 1.793311 | C13: 1.8324599 | D13: 1.793311 | E13: 1.793311 | F13: 1.793311 | G13: 1.793311 | H13: 1.793311 | I13: 2.2528655 | J13: 1.793311 | K13: 2.2528655
... A68: 0.66 | B68: 16.675863 | C68: 86.721657 | D68: 16.675883 | E68: 16.676923 | F68: 16.685166 | G68: 16.734763 | H68: 17.005404 | I68: 23.337818 | J68: 17.06797 | K68: 33.266388
A69: 0.67 | B69: 17.199841 | D69: 17.199877 | E69: 17.201097 | F69: 17.21056 | G69: 17.2665 | H69: 17.567695 | I69: 24.214373 | J69: 17.647173 | K69: 36.196589
A70: 0.68 | B70: 17.743825 | D70: 17.743883 | E70: 17.745299 | F70: 17.756105 | G70: 17.81878 | H70: 18.149793 | I70: 25.138659 | J70: 18.249484 | K70: 39.850882
A71: 0.69 | B71: 18.306733 | D71: 18.306816 | E71: 18.308446 | F71: 18.320738 | G71: 18.390646 | H71: 18.75159 | I71: 26.112223 | J71: 18.874326 | K71: 45.021696
A72: 0.7 | B72: 18.891535 | D72: 18.891659 | E72: 18.893614 | F72: 18.908185 | G72: 18.989671 | H72: 19.373401 | I72: 27.134976 | J72: 19.523495 | K72: 53.350086
A73: 0.71 | B73: 19.512492 | D73: 19.512678 | E73: 19.515073 | F73: 19.532675 | G73: 19.628603 | H73: 20.028556 | I73: 28.207039 | J73: 20.212235 | K73: 70.754839
A74: 0.72 | B74: 20.170786 | D74: 20.171052 | E74: 20.173987 | F74: 20.195077 | G74: 20.307551 | H74: 20.721949 | I74: 29.346212 | J74: 20.944833
A75: 0.73 | B75: 20.867961 | D75: 20.868325 | E75: 20.871934 | F75: 20.897174 | G75: 21.029252 | H75: 21.456236 | I75: 30.578835 | J75: 21.721976
A76: 0.74 | B76: 21.608351 | D76: 21.608833 | E76: 21.613261 | F76: 21.643364 | G76: 21.797902 | H76: 22.232161 | I76: 31.932314 | J76: 22.547524
A77: 0.75 | B77: 22.395237 | D77: 22.395859 | E77: 22.401284 | F77: 22.437135 | G77: 22.617748 | H77: 23.051159 | I77: 33.421176 | J77: 23.421198
A78: 0.76 | B78: 23.230132 | D78: 23.230908 | E78: 23.237488 | F78: 23.279893 | G78: 23.489465 | H78: 23.91199 | I78: 35.061546 | J78: 24.343803
A79: 0.77 | B79: 24.111823 | D79: 24.112779 | E79: 24.12066 | F79: 24.17046 | G79: 24.412123 | H79: 24.816471 | I79: 36.848252 | J79: 25.333372
A80: 0.78 | B80: 25.044894 | D80: 25.046105 | E80: 25.055738 | F80: 25.115536 | G80: 25.400936 | H80: 25.786045 | I80: 38.780537 | J80: 26.398267
A81: 0.79 | B81: 26.044666 | D81: 26.046207 | E81: 26.058053 | F81: 26.12987 | G81: 26.464532 | H81: 26.828767 | I81: 40.859787 | J81: 27.546103
A82: 0.8 | B82: 27.112251 | D82: 27.114205 | E82: 27.12873 | F82: 27.214561 | G82: 27.608006 | H82: 27.950788 | I82: 43.083072 | J82: 28.788457
A83: 0.81 | B83: 28.257952 | D83: 28.26048 | E83: 28.278569 | F83: 28.382292 | G83: 28.848012 | H83: 29.160874 | I83: 45.452504 | J83: 30.143136
A84: 0.82 | B84: 29.49227 | D84: 29.495511 | E84: 29.518012 | F84: 29.642674 | G84: 30.191485 | H84: 30.462898 | I84: 48.001843 | J84: 31.731512
A85: 0.83 | B85: 30.826009 | D85: 30.830182 | E85: 30.85842 | F85: 31.00942 | G85: 31.656645 | H85: 31.925917 | I85: 50.798137 | J85: 33.605909
... A92: 0.9 | B92: 43.355855 | D92: 43.378205 | E92: 43.489249 | F92: 43.97051 | G92: 45.749864 | H92: 48.802448 | I92: 79.27623 | J92: 61.992607

Sheet SC1_2
A1: reduction | B1: $SC_{0}$ | C1: $C_{1}(_x000C_rac{1}{3}, 3)$ | D1: $C_{1}(0, 3)$ | E1: $C_{1}(0, 2)$ | F1: $C_{1}(0, 1.5)$ | G1: $C_{1}(0, 1.25)$ | H1: $C_{2}(2)$ | I1: $C_{2}(1)$ | J1: $C_{3}(0,2,2)$ | K1: $C_{3}(0,2,1)$
A2: 0 | B2: 7.8350819e-11 | C2: 7.8350819e-11 | D2: 7.8350819e-11 | E2: 7.8350819e-11 | F2: 7.8350819e-11 | G2: 7.8350819e-11 | H2: 7.8350819e-11 | I2: 7.8350819e-11 | J2: 7.8350819e-11 | K2: 7.8350819e-11
A3: 0.01 | B3: 0.17562552 | C3: 0.18129116 | D3: 0.17562552 | E3: 0.17562552 | F3: 0.17562552 | G3: 0.17562552 | H3: 0.17562552 | I3: 0.22648081 | J3: 0.17562552 | K3: 0.22648081
A4: 0.02 | B4: 0.3698516 | C4: 0.37811079 | D4: 0.3698516 | E4: 0.3698516 | F4: 0.3698516 | G4: 0.3698516 | H4: 0.3698516 | I4: 0.47258142 | J4: 0.3698516 | K4: 0.47258142
A5: 0.03 | B5: 0.56716618 | C5: 0.57620347 | D5: 0.56716618 | E5: 0.56716618 | F5: 0.56716618 | G5: 0.56716618 | H5: 0.56716618 | I5: 0.7211604 | J5: 0.56716618 | K5: 0.7211604
A6: 0.04 | B6: 0.76518373 | C6: 0.77459313 | D6: 0.76518373 | E6: 0.76518373 | F6: 0.76518373 | G6: 0.76518373 | H6: 0.76518373 | I6: 0.97031487 | J6: 0.76518373 | K6: 0.97031487
A7: 0.05 | B7: 0.96347091 | C7: 0.97322518 | D7: 0.96347091 | E7: 0.96347091 | F7: 0.96347091 | G7: 0.96347091 | H7: 0.96347091 | I7: 1.2196922 | J7: 0.96347091 | K7: 1.2196922
A8: 0.06 | B8: 1.1618897 | C8: 1.1746346 | D8: 1.1618897 | E8: 1.1618897 | F8: 1.1618897 | G8: 1.1618897 | H8: 1.1618897 | I8: 1.4691789 | J8: 1.1618897 | K8: 1.4691789
A9: 0.07 | B9: 1.3603825 | C9: 1.3785908 | D9: 1.3603825 | E9: 1.3603825 | F9: 1.3603825 | G9: 1.3603825 | H9: 1.3603825 | I9: 1.7193216 | J9: 1.3603825 | K9: 1.7193216
A10: 0.08 | B10: 1.559981 | C10: 1.5852081 | D10: 1.559981 | E10: 1.559981 | F10: 1.559981 | G10: 1.559981 | H10: 1.559981 | I10: 1.9720581 | J10: 1.559981 | K10: 1.9720581
A11: 0.09 | B11: 1.7619518 | C11: 1.7944108 | D11: 1.7619518 | E11: 1.7619518 | F11: 1.7619518 | G11: 1.7619518 | H11: 1.7619518 | I11: 2.2267217 | J11: 1.7619518 | K11: 2.2267217
A12: 0.1 | B12: 1.965591 | C12: 2.0067143 | D12: 1.965591 | E12: 1.965591 | F12: 1.965591 | G12: 1.965591 | H12: 1.965591 | I12: 2.4827195 | J12: 1.965591 | K12: 2.4827195
A13: 0.11 | B13: 2.1706664 | C13: 2.2221895 | D13: 2.1706664 | E13: 2.1706664 | F13: 2.1706664 | G13: 2.1706664 | H13: 2.1706664 | I13: 2.7405104 | J13: 2.1706664 | K13: 2.7405287
... A67: 0.65 | B67: 20.664933 | C67: 301.38784 | D67: 20.66593 | E67: 20.674282 | F67: 20.717178 | G67: 20.900191 | H67: 21.277821 | I67: 30.602222 | J67: 21.447535 | K67: 61.254515
A68: 0.66 | B68: 21.336802 | D68: 21.338148 | E68: 21.348425 | F68: 21.400297 | G68: 21.617458 | H68: 22.013392 | I68: 31.946424 | J68: 22.222901 | K68: 79.952605
A69: 0.67 | B69: 22.055847 | D69: 22.057655 | E69: 22.070321 | F69: 22.133015 | G69: 22.389294 | H69: 22.797646 | I69: 33.380147 | J69: 23.057568 | K69: 137.59954
A70: 0.68 | B70: 22.823618 | D70: 22.826049 | E70: 22.841706 | F70: 22.917848 | G70: 23.220985 | H70: 23.635704 | I70: 34.919111 | J70: 23.956013
A71: 0.69 | B71: 23.645191 | D71: 23.648445 | E71: 23.667827 | F71: 23.760299 | G71: 24.116871 | H71: 24.53108 | I71: 36.574126 | J71: 24.919893
A72: 0.7 | B72: 24.522455 | D72: 24.5267 | E72: 24.550477 | F72: 24.661612 | G72: 25.077707 | H72: 25.483569 | I72: 38.353994 | J72: 25.951732
A73: 0.71 | B73: 25.455445 | D73: 25.460886 | E73: 25.489836 | F73: 25.621982 | G73: 26.105994 | H73: 26.494887 | I73: 40.264481 | J73: 27.062681
A74: 0.72 | B74: 26.443259 | D74: 26.450273 | E74: 26.485791 | F74: 26.644755 | G74: 27.215285 | H74: 27.575327 | I74: 42.309328 | J74: 28.25405
A75: 0.73 | B75: 27.495229 | D75: 27.504324 | E75: 27.548233 | F75: 27.739815 | G75: 28.408262 | H75: 28.725377 | I75: 44.492322 | J75: 29.539071
A76: 0.74 | B76: 28.613022 | D76: 28.624635 | E76: 28.678516 | F76: 28.908252 | G76: 29.692851 | H76: 29.955577 | I76: 46.813966 | J76: 30.924606
A77: 0.75 | B77: 29.802834 | D77: 29.817842 | E77: 29.884632 | F77: 30.163028 | G77: 31.092262 | H77: 31.273187 | I77: 49.307644 | J77: 32.449393
A78: 0.76 | B78: 31.081618 | D78: 31.101197 | E78: 31.184469 | F78: 31.521183 | G78: 32.613653 | H78: 32.68451 | I78: 52.023033 | J78: 34.224829
A79: 0.77 | B79: 32.453461 | D79: 32.478876 | E79: 32.582022 | F79: 32.988981 | G79: 34.289959 | H79: 34.249433 | I79: 54.96366 | J79: 36.306515
A80: 0.78 | B80: 33.935446 | D80: 33.969163 | E80: 34.099258 | F80: 34.597773 | G80: 36.151863 | H80: 36.003005 | I80: 58.138868 | J80: 38.702705
A81: 0.79 | B81: 35.547603 | D81: 35.591849 | E81: 35.754721 | F81: 36.358857 | G81: 38.209578 | H81: 37.950583 | I81: 61.599266 | J81: 41.48927
... A88: 0.86 | B88: 50.958838 | D88: 51.211113 | E88: 51.924773 | F88: 53.927719 | G88: 60.859056 | H88: 58.821193 | I88: 94.485009 | J88: 96.252587
A89: 0.87 | B89: 53.848698 | D89: 54.163387 | E89: 55.01977 | F89: 57.362921 | H89: 63.077101 | I89: 101.03722 | J89: 149.05998
A90: 0.88 | B90: 56.917804 | D90: 57.306773 | E90: 58.35111 | F90: 61.236056 | H90: 67.6981 | I90: 108.29654
A91: 0.89 | B91: 60.22276 | D91: 60.738578 | E91: 62.064062 | F91: 67.151533 | H91: 72.788544 | I91: 116.38309
A92: 0.9 | B92: 63.882092 | D92: 64.67768 | E92: 66.993404 | F92: 80.273543 | H92: 78.556082 | I92: 125.46658

Sheet SC1_2_3_up
A1: reduction | B1: $SC_{0}$ | C1: $C_{1}(_x000C_rac{1}{3}, 3)$ | D1: $C_{1}(0, 3)$ | E1: $C_{1}(0, 2)$ | F1: $C_{1}(0, 1.5)$ | G1: $C_{1}(0, 1.25)$ | H1: $C_{2}(2)$ | I1: $C_{2}(1)$ | J1: $C_{3}(0,2,2)$ | K1: $C_{3}(0,2,1)$
A2: 0 | B2: 7.8350819e-11 | C2: 7.8350819e-11 | D2: 7.8350819e-11 | E2: 7.8350819e-11 | F2: 7.8350819e-11 | G2: 7.8350819e-11 | H2: 7.8350819e-11 | I2: 7.8350819e-11 | J2: 7.8350819e-11 | K2: 7.8350819e-11
A3: 0.01 | B3: 0.21700858 | C3: 0.22136804 | D3: 0.21700858 | E3: 0.21700858 | F3: 0.21700858 | G3: 0.21700858 | H3: 0.21700858 | I3: 0.24677041 | J3: 0.21700858 | K3: 0.24677041
A4: 0.02 | B4: 0.45345158 | C4: 0.46845405 | D4: 0.45345158 | E4: 0.45345158 | F4: 0.45345158 | G4: 0.45345158 | H4: 0.45345158 | I4: 0.52386006 | J4: 0.45345158 | K4: 0.52386006
A5: 0.03 | B5: 0.70268108 | C5: 0.7211684 | D5: 0.70268108 | E5: 0.70268108 | F5: 0.70268108 | G5: 0.70268108 | H5: 0.70268108 | I5: 0.81298022 | J5: 0.70268108 | K5: 0.81298022
A6: 0.04 | B6: 0.95488227 | C6: 0.99759175 | D6: 0.95488227 | E6: 0.95488227 | F6: 0.95488227 | G6: 0.95488227 | H6: 0.95488227 | I6: 1.1157762 | J6: 0.95488227 | K6: 1.1157762
A7: 0.05 | B7: 1.2144755 | C7: 1.2957344 | D7: 1.2144755 | E7: 1.2144755 | F7: 1.2144755 | G7: 1.2144755 | H7: 1.2144755 | I7: 1.4626816 | J7: 1.2144755 | K7: 1.4626816
A8: 0.06 | B8: 1.4963876 | C8: 1.6079909 | D8: 1.4963876 | E8: 1.4963876 | F8: 1.4963876 | G8: 1.4963876 | H8: 1.4963876 | I8: 1.8326084 | J8: 1.4963876 | K8: 1.8326084
A9: 0.07 | B9: 1.791733 | C9: 1.9353733 | D9: 1.791733 | E9: 1.791733 | F9: 1.791733 | G9: 1.7917505 | H9: 1.791733 | I9: 2.2155117 | J9: 1.791733 | K9: 2.2155117
A10: 0.08 | B10: 2.0978515 | C10: 2.276108 | D10: 2.0978515 | E10: 2.0978515 | F10: 2.0978515 | G10: 2.0979201 | H10: 2.0978515 | I10: 2.6144807 | J10: 2.0978515 | K10: 2.6144807
A11: 0.09 | B11: 2.4119863 | C11: 2.6288842 | D11: 2.4119863 | E11: 2.4119863 | F11: 2.4119863 | G11: 2.4121558 | H11: 2.4119863 | I11: 3.0278092 | J11: 2.4119863 | K11: 3.0278528
A12: 0.1 | B12: 2.7367612 | C12: 2.9931946 | D12: 2.7367612 | E12: 2.7367612 | F12: 2.7367612 | G12: 2.7370838 | H12: 2.7367612 | I12: 3.4541893 | J12: 2.7367612 | K12: 3.4556001
A13: 0.11 | B13: 3.0714223 | C13: 3.3705055 | D13: 3.0714223 | E13: 3.0714223 | F13: 3.0714223 | G13: 3.0719462 | H13: 3.0714223 | I13: 3.8936462 | J13: 3.0714223 | K13: 3.8984376
... A54: 0.52 | B54: 28.721531 | C54: 59.018173 | D54: 28.788567 | E54: 29.04562 | F54: 29.939413 | G54: 32.60241 | H54: 29.570152 | I54: 48.225606 | J54: 30.314694 | K54: 206.21679
A55: 0.53 | B55: 29.94392 | C55: 65.111136 | D55: 30.027895 | E55: 30.334797 | F55: 31.375043 | G55: 34.543122 | H55: 30.884511 | I55: 50.651826 | J55: 31.75846
A56: 0.54 | B56: 31.219525 | C56: 73.588094 | D56: 31.322785 | E56: 31.686269 | F56: 32.889737 | G56: 36.688929 | H56: 32.256549 | I56: 53.190335 | J56: 33.274063
A57: 0.55 | B57: 32.548259 | C57: 85.941156 | D57: 32.673983 | E57: 33.102566 | F57: 34.496217 | G57: 39.08341 | H57: 33.682303 | I57: 55.856895 | J57: 34.867992
A58: 0.56 | B58: 33.931307 | C58: 104.42286 | D58: 34.082284 | E58: 34.58593 | F58: 36.20129 | G58: 41.757801 | H58: 35.163903 | I58: 58.663426 | J58: 36.575323
A59: 0.57 | B59: 35.367828 | C59: 133.78467 | D59: 35.549948 | E59: 36.142263 | F59: 38.01372 | G59: 44.76157 | H59: 36.707149 | I59: 61.626478 | J59: 38.434818
A60: 0.58 | B60: 36.862311 | C60: 185.74509 | D60: 37.080808 | E60: 37.778553 | F60: 39.953672 | G60: 48.110381 | H60: 38.345732 | I60: 64.769396 | J60: 40.445156
A61: 0.59 | B61: 38.417941 | D61: 38.680384 | E61: 39.502064 | F61: 42.030585 | G61: 51.892951 | H61: 40.0903 | I61: 68.111256 | J61: 42.605521
A62: 0.6 | B62: 40.038698 | D62: 40.354384 | E62: 41.326946 | F62: 44.246089 | G62: 56.228518 | H62: 41.936304 | I62: 71.664318 | J62: 44.933605
A63: 0.61 | B63: 41.734524 | D63: 42.115233 | E63: 43.253617 | F63: 46.603093 | G63: 61.256029 | H63: 43.880187 | I63: 75.44466 | J63: 47.466528
A64: 0.62 | B64: 43.50883 | D64: 43.962644 | E64: 45.278258 | F64: 49.100899 | G64: 68.238112 | H64: 45.928516 | I64: 79.479468 | J64: 50.26347
A65: 0.63 | B65: 45.358183 | D65: 45.893925 | E65: 47.404884 | F65: 51.764037 | H65: 48.104094 | I65: 83.789371 | J65: 53.390142
A66: 0.64 | B66: 47.28049 | D66: 47.910806 | E66: 49.639331 | F66: 54.624627 | H66: 50.441149 | I66: 88.374234 | J66: 56.871689
A67: 0.65 | B67: 49.281482 | D67: 50.021323 | E67: 51.993546 | F67: 57.702988 | H67: 52.947651 | I67: 93.228107 | J67: 60.731481
A68: 0.66 | B68: 51.366782 | D68: 52.235772 | E68: 54.477459 | F68: 61.010752 | H68: 55.630778 | I68: 98.34269 | J68: 65.131267
A69: 0.67 | B69: 53.549072 | D69: 54.563276 | E69: 57.102863 | F69: 64.573853 | H69: 58.49279 | I69: 103.72318 | J69: 70.383469
A70: 0.68 | B70: 55.829227 | D70: 57.008248 | E70: 59.87562 | F70: 68.421485 | H70: 61.533584 | I70: 109.42239 | J70: 76.6966
A71: 0.69 | B71: 58.209568 | D71: 59.573455 | E71: 62.800142 | F71: 72.759126 | H71: 64.751674 | I71: 115.55126 | J71: 84.310368
A72: 0.7 | B72: 60.68818 | D72: 62.257125 | E72: 65.888247 | F72: 78.890564 | H72: 68.184311 | I72: 122.13091 | J72: 94.851325
A73: 0.71 | B73: 63.261403 | D73: 65.063848 | E73: 69.138753 | F73: 90.998841 | H73: 71.890727 | I73: 129.26507 | J73: 114.26003
A74: 0.72 | B74: 65.928032 | D74: 68.000501 | E74: 72.604609 | F74: 117.28889 | H74: 75.873981 | I74: 137.14619 | J74: 165.23704
A75: 0.73 | B75: 68.698728 | D75: 71.069685 | E75: 76.418118 | H75: 80.123938 | I75: 145.88256
A76: 0.74 | B76: 71.579312 | D76: 74.315227 | E76: 81.177721 | H76: 84.648102 | I76: 155.57342
A77: 0.75 | B77: 74.580382 | D77: 77.811409 | E77: 87.43971 | H77: 89.44015 | I77: 166.27407
A78: 0.76 | B78: 77.745668 | D78: 81.879959 | E78: 96.052863 | H78: 94.575638 | I78: 178.10857
A79: 0.77 | B79: 81.159123 | D79: 86.766135 | E79: 110.06014 | H79: 100.20082 | I79: 191.29054
A80: 0.78 | B80: 85.015163 | D80: 92.700661 | E80: 140.40186 | H80: 106.40295 | I80: 205.9852
...

Sheet SC1_2_3
A1: reduction | B1: $SC_{0}$ | C1: $C_{1}(_x000C_rac{1}{3}, 3)$ | D1: $C_{1}(0, 3)$ | E1: $C_{1}(0, 2)$ | F1: $C_{1}(0, 1.5)$ | G1: $C_{1}(0, 1.25)$ | H1: $C_{2}(2)$ | I1: $C_{2}(1)$ | J1: $C_{3}(0,2,2)$ | K1: $C_{3}(0,2,1)$
A2: 0 | B2: 7.8350819e-11 | C2: 7.8350819e-11 | D2: 7.8350819e-11 | E2: 7.8350819e-11 | F2: 7.8350819e-11 | G2: 7.8350819e-11 | H2: 7.8350819e-11 | I2: 7.8350819e-11 | J2: 7.8350819e-11 | K2: 7.8350819e-11
A3: 0.01 | B3: 0.29844834 | C3: 0.29859647 | D3: 0.29844834 | E3: 0.29844834 | F3: 0.29844834 | G3: 0.29844834 | H3: 0.29844834 | I3: 0.33110699 | J3: 0.29844834 | K3: 0.33110699
A4: 0.02 | B4: 0.59803163 | C4: 0.60026536 | D4: 0.59803163 | E4: 0.59803163 | F4: 0.59803163 | G4: 0.59803163 | H4: 0.59803163 | I4: 0.66293401 | J4: 0.59803163 | K4: 0.66293401
A5: 0.03 | B5: 0.90039804 | C5: 0.90484977 | D5: 0.90039804 | E5: 0.90039804 | F5: 0.90039804 | G5: 0.90039804 | H5: 0.90039804 | I5: 0.99900331 | J5: 0.90039804 | K5: 0.99900331
A6: 0.04 | B6: 1.2047614 | C6: 1.211505 | D6: 1.2047614 | E6: 1.2047614 | F6: 1.2047614 | G6: 1.2047614 | H6: 1.2047614 | I6: 1.3369318 | J6: 1.2047614 | K6: 1.3369318
A7: 0.05 | B7: 1.5099222 | C7: 1.5218168 | D7: 1.5099222 | E7: 1.5099222 | F7: 1.5099222 | G7: 1.5099222 | H7: 1.5099222 | I7: 1.6774076 | J7: 1.5099222 | K7: 1.6774076
A8: 0.06 | B8: 1.8172576 | C8: 1.8340886 | D8: 1.8172576 | E8: 1.8172576 | F8: 1.8172576 | G8: 1.8172576 | H8: 1.8172576 | I8: 2.0219042 | J8: 1.8172576 | K8: 2.0219042
A9: 0.07 | B9: 2.1271472 | C9: 2.1510089 | D9: 2.1271472 | E9: 2.1271472 | F9: 2.1271472 | G9: 2.1271473 | H9: 2.1271472 | I9: 2.3687187 | J9: 2.1271472 | K9: 2.3687187
A10: 0.08 | B10: 2.4386176 | C10: 2.4818922 | D10: 2.4386176 | E10: 2.4386176 | F10: 2.4386176 | G10: 2.4386281 | H10: 2.4386176 | I10: 2.7172843 | J10: 2.4386176 | K10: 2.7172843
A11: 0.09 | B11: 2.7511329 | C11: 2.8234599 | D11: 2.7511329 | E11: 2.7511329 | F11: 2.7511329 | G11: 2.7511762 | H11: 2.7511329 | I11: 3.0779917 | J11: 2.7511329 | K11: 3.0779917
A12: 0.1 | B12: 3.0658347 | C12: 3.1754371 | D12: 3.0658347 | E12: 3.0658347 | F12: 3.0658347 | G12: 3.0659353 | H12: 3.0658347 | I12: 3.45522 | J12: 3.0658347 | K12: 3.45522
A13: 0.11 | B13: 3.3898033 | C13: 3.536857 | D13: 3.3898033 | E13: 3.3898033 | F13: 3.3898033 | G13: 3.3899962 | H13: 3.3898033 | I13: 3.8450673 | J13: 3.3898033 | K13: 3.8450805
... A64: 0.62 | B64: 34.148215 | C64: 124.91985 | D64: 34.172318 | E64: 34.279548 | F64: 34.693172 | G64: 35.979166 | H64: 34.481312 | I64: 49.892319 | J64: 34.700634 | K64: 82.56119
A65: 0.63 | B65: 35.142175 | D65: 35.170357 | E65: 35.292535 | F65: 35.758306 | G65: 37.197403 | H65: 35.575861 | I65: 51.710564 | J65: 35.843446 | K65: 99.646461
A66: 0.64 | B66: 36.168611 | D66: 36.201792 | E66: 36.342011 | F66: 36.866965 | G66: 38.470314 | H66: 36.732966 | I66: 53.624981 | J66: 37.055596
A67: 0.65 | B67: 37.230404 | D67: 37.269405 | E67: 37.430109 | F67: 38.017775 | G67: 39.808252 | H67: 37.957159 | I67: 55.651864 | J67: 38.345268
A68: 0.66 | B68: 38.328244 | D68: 38.373664 | E68: 38.556461 | F68: 39.209629 | G68: 41.217207 | H68: 39.24864 | I68: 57.786353 | J68: 39.712429
A69: 0.67 | B69: 39.462185 | D69: 39.514715 | E69: 39.721343 | F69: 40.447573 | G69: 42.70132 | H69: 40.606875 | I69: 60.023215 | J69: 41.166325
A70: 0.68 | B70: 40.631903 | D70: 40.692677 | E70: 40.927386 | F70: 41.738213 | G70: 44.26558 | H70: 42.03916 | I70: 62.359667 | J70: 42.714072
A71: 0.69 | B71: 41.844186 | D71: 41.914954 | E71: 42.181611 | F71: 43.080954 | G71: 45.909368 | H71: 43.547563 | I71: 64.801178 | J71: 44.361957
A72: 0.7 | B72: 43.100509 | D72: 43.182241 | E72: 43.483011 | F72: 44.479967 | G72: 47.632557 | H72: 45.133899 | I72: 67.37024 | J72: 46.129496
A73: 0.71 | B73: 44.400041 | D73: 44.494164 | E73: 44.834127 | F73: 45.938569 | G73: 49.433197 | H73: 46.806638 | I73: 70.069941 | J73: 48.036994
A74: 0.72 | B74: 45.746374 | D74: 45.855037 | E74: 46.238477 | F74: 47.455559 | G74: 51.316712 | H74: 48.569324 | I74: 72.896557 | J74: 50.135112
A75: 0.73 | B75: 47.140744 | D75: 47.265339 | E75: 47.695786 | F75: 49.031052 | G75: 53.325129 | H75: 50.439616 | I75: 75.884934 | J75: 52.431515
A76: 0.74 | B76: 48.585131 | D76: 48.727186 | E76: 49.207535 | F76: 50.664876 | G76: 55.567861 | H76: 52.428874 | I76: 79.060842 | J76: 54.921999
A77: 0.75 | B77: 50.078821 | D77: 50.239723 | E77: 50.772056 | F77: 52.362293 | G77: 58.329825 | H77: 54.533096 | I77: 82.459517 | J77: 57.656926
... A80: 0.78 | B80: 54.867421 | D80: 55.110092 | E80: 55.87492 | F80: 58.195373 | G80: 77.089945 | H80: 61.627987 | I80: 94.164912 | J80: 68.248625
A81: 0.79 | B81: 56.624233 | D81: 56.917699 | E81: 57.821906 | F81: 60.649477 | H81: 64.303436 | I81: 98.675361 | J81: 73.322601
A82: 0.8 | B82: 58.505557 | D82: 58.875923 | E82: 59.999729 | F82: 63.447623 | H82: 67.233487 | I82: 103.63999 | J82: 80.058148
A83: 0.81 | B83: 60.574704 | D83: 61.054255 | E83: 62.432717 | F83: 66.587559 | H83: 70.432144 | I83: 109.37293 | J83: 91.016684
A84: 0.82 | B84: 62.843882 | D84: 63.456989 | E84: 65.114432 | F84: 70.332896 | H84: 73.922578 | I84: 115.89592 | J84: 114.83409
A85: 0.83 | B85: 65.313618 | D85: 66.079999 | E85: 68.047384 | F85: 75.326962 | H85: 77.724829 | I85: 123.36159
A86: 0.84 | B86: 67.988321 | D86: 68.941745 | E86: 71.365967 | F86: 83.21142 | H86: 81.890659 | I86: 132.21003
A87: 0.85 | B87: 70.885936 | D87: 72.136092 | E87: 75.358664 | F87: 101.28387 | H87: 86.477429 | I87: 142.94616
A88: 0.86 | B88: 74.127534 | D88: 75.882391 | E88: 80.384593 | H88: 91.845894 | I88: 155.76409
A89: 0.87 | B89: 77.854956 | D89: 80.476626 | E89: 87.255346 | H89: 98.54266 | I89: 171.14086
A90: 0.88 | B90: 82.314338 | D90: 86.43778 | E90: 98.587927 | H90: 106.96868 | I90: 190.0015
A91: 0.89 | B91: 87.793133 | D91: 95.016208 | E91: 123.53714 | H91: 117.24175 | I91: 213.08893
A92: 0.9 | B92: 94.998468 | D92: 108.23722 | E92: 207.45173 | H92: 129.95919 | I92: 241.33172

Sheet sector_SC1
A1: In % | B1: msci_gics_sector | C1: 0.0 | D1: 0.3 | E1: 0.4 | F1: 0.5 | G1: 0.6 | H1: 0.7 | I1: 0.8 | J1: 0.9
B2: Communication Services | C2: 7.5792678 | D2: 7.7068736 | E2: 7.7692937 | F2: 7.8461248 | G2: 7.952653 | H2: 8.1194087 | I2: 8.4436418 | J2: 9.0730241
B3: Consumer Discretionary | C3: 10.558518 | D3: 10.705793 | E3: 10.774188 | F3: 10.854473 | G3: 10.956123 | H3: 11.091584 | I3: 11.290373 | J3: 11.493756
B4: Consumer Staples | C4: 7.8015336 | D4: 7.9411317 | E4: 7.9997594 | F4: 8.059612 | G4: 8.1195574 | H4: 8.1448945 | I4: 7.9982631 | J4: 7.3679719
B5: Energy | C5: 4.9892566 | D5: 4.8468098 | E5: 4.7433891 | F5: 4.571013 | G5: 4.2495036 | H5: 3.7709722 | I5: 2.8691233 | J5: 1.1891986
B6: Financials | C6: 13.563798 | D6: 13.901875 | E6: 14.070675 | F6: 14.2852 | G6: 14.59428 | H6: 15.085169 | I6: 16.027376 | J6: 17.641116
B7: Health Care | C7: 14.14539 | D7: 14.329714 | E7: 14.417032 | F7: 14.521111 | G7: 14.658333 | H7: 14.848621 | I7: 15.131303 | J7: 15.510391
B8: Industrials | C8: 9.8960771 | D8: 9.9852301 | E8: 9.9876082 | F8: 9.9916204 | G8: 10.004905 | H8: 9.97571 | I8: 9.7549589 | J8: 9.466328
B9: Information Technology | C9: 21.078442 | D9: 21.309322 | E9: 21.424142 | F9: 21.569006 | G9: 21.772889 | H9: 22.083976 | I9: 22.618191 | J9: 23.358708
B10: Materials | C10: 4.2830313 | D10: 4.0071955 | E10: 3.855885 | F10: 3.6469537 | G10: 3.3463735 | H10: 2.8373054 | I10: 2.0012967 | J10: 1.1617944
B11: Real Estate | C11: 2.8970755 | D11: 3.0007223 | E11: 3.0501549 | F11: 3.1079993 | G11: 3.1802478 | H11: 3.2769867 | I11: 3.4053264 | J11: 3.3996433
B12: Utilities | C12: 3.2076091 | D12: 2.2653328 | E12: 1.9078732 | F12: 1.5468861 | G12: 1.165135 | H12: 0.76537205 | I12: 0.46014732 | J12: 0.33806871

Sheet sector_SC1_2
A1: In % | B1: msci_gics_sector | C1: 0.0 | D1: 0.3 | E1: 0.4 | F1: 0.5 | G1: 0.6 | H1: 0.7 | I1: 0.8 | J1: 0.9
B2: Communication Services | C2: 7.5792678 | D2: 7.7446801 | E2: 7.8283689 | F2: 7.9322504 | G2: 8.0760512 | H2: 8.3109779 | I2: 8.6809858 | J2: 9.0239746
B3: Consumer Discretionary | C3: 10.558518 | D3: 10.713796 | E3: 10.777201 | F3: 10.839154 | G3: 10.91022 | H3: 11.075614 | I3: 11.17605 | J3: 10.687171
B4: Consumer Staples | C4: 7.8015336 | D4: 7.9762557 | E4: 8.0488063 | F4: 8.1195114 | G4: 8.1699549 | H4: 8.0836494 | I4: 7.5460036 | J4: 5.8898406
B5: Energy | C5: 4.9892566 | D5: 4.8034671 | E5: 4.6550244 | F5: 4.4037076 | G5: 3.9940561 | H5: 3.2964761 | I5: 1.9976207 | J5: 0.14484903
B6: Financials | C6: 13.563798 | D6: 14.052824 | E6: 14.317251 | F6: 14.672191 | G6: 15.202161 | H6: 16.193486 | I6: 18.298535 | J6: 23.114119
B7: Health Care | C7: 14.14539 | D7: 14.398851 | E7: 14.526361 | F7: 14.683851 | G7: 14.895206 | H7: 15.20866 | I7: 15.725129 | J7: 16.018106
B8: Industrials | C8: 9.8960771 | D8: 10.039339 | E8: 10.068945 | F8: 10.126533 | G8: 10.189515 | H8: 10.1165 | I8: 9.8263328 | J8: 8.8628987
B9: Information Technology | C9: 21.078442 | D9: 21.383876 | E9: 21.541674 | F9: 21.742798 | G9: 22.019303 | H9: 22.443876 | I9: 23.085766 | J9: 23.928713
B10: Materials | C10: 4.2830313 | D10: 3.8042729 | E10: 3.5371916 | F10: 3.1966973 | G10: 2.6931799 | H10: 2.0438512 | I10: 1.1985528 | J10: 0.58765274
B11: Real Estate | C11: 2.8970755 | D11: 2.9763732 | E11: 3.0003579 | F11: 3.007513 | G11: 2.9682785 | H11: 2.7742872 | I11: 2.2708344 | J11: 1.5022923
B12: Utilities | C12: 3.2076091 | D12: 2.1062659 | E12: 1.6988195 | F12: 1.2757924 | G12: 0.8820741 | H12: 0.45262181 | I12: 0.19419056 | J12: 0.24038181

Sheet sector_SC1_2_3_up
A1: In % | B1: msci_gics_sector | C1: 0.0 | D1: 0.3 | E1: 0.4 | F1: 0.5 | G1: 0.6 | H1: 0.7 | I1: 0.8 | J1: 0.9 | L1: Diff (in bps) | M1: msci_gics_sector | N1: 0.0 | O1: 0.3 | P1: 0.4 | Q1: 0.5 | R1: 0.6 | S1: 0.7 | T1: 0.8 | U1: 0.9
B2: Communication Services | C2: 7.5792678 | D2: 7.9510804 | E2: 8.2846586 | F2: 8.8093344 | G2: 9.6117281 | H2: 10.500805 | I2: 10.884823 | J2: 0.18015018 | M2: Communication Services | N2: =ABS(C2-sector_SC1_2_3_up!C16) * 100 -> 0.073217565 | O2: =ABS(D2-sector_SC1_2_3_up!D16) * 100 -> 0.89196498 | P2: =ABS(E2-sector_SC1_2_3_up!E16) * 100 -> 1.5341371 | Q2: =ABS(F2-sector_SC1_2_3_up!F16) * 100 -> 0.93343734 | R2: =ABS(G2-sector_SC1_2_3_up!G16) * 100 -> 4.1728149 | S2: =ABS(H2-sector_SC1_2_3_up!H16) * 100 -> 4.0804573 | T2: =ABS(I2-sector_SC1_2_3_up!I16) * 100 -> 14.482323 | U2: =ABS(J2-sector_SC1_2_3_up!J16) * 100 -> 0.015018467
B3: Consumer Discretionary | C3: 10.558518 | D3: 10.761278 | E3: 10.771121 | F3: 10.673164 | G3: 10.349654 | H3: 9.4356628 | I3: 6.8574848 | J3: 0 | M3: Consumer Discretionary | N3: =ABS(C3-sector_SC1_2_3_up!C17) * 100 -> 0.14816911 | O3: =ABS(D3-sector_SC1_2_3_up!D17) * 100 -> 3.8722438 | P3: =ABS(E3-sector_SC1_2_3_up!E17) * 100 -> 9.8878811 | Q3: =ABS(F3-sector_SC1_2_3_up!F17) * 100 -> 3.6836417 | R3: =ABS(G3-sector_SC1_2_3_up!G17) * 100 -> 9.034553 | S3: =ABS(H3-sector_SC1_2_3_up!H17) * 100 -> 5.4337213 | T3: =ABS(I3-sector_SC1_2_3_up!I17) * 100 -> 10.748478 | U3: =ABS(J3-sector_SC1_2_3_up!J17) * 100 -> 0
B4: Consumer Staples | C4: 7.8015336 | D4: 7.4436726 | E4: 6.9931804 | F4: 6.1652552 | G4: 4.9404117 | H4: 3.1183277 | I4: 0.93246182 | J4: 0.23912224 | M4: Consumer Staples | N4: =ABS(C4-sector_SC1_2_3_up!C18) * 100 -> 0.15335796 | O4: =ABS(D4-sector_SC1_2_3_up!D18) * 100 -> 7.3672617 | P4: =ABS(E4-sector_SC1_2_3_up!E18) * 100 -> 16.318045 | Q4: =ABS(F4-sector_SC1_2_3_up!F18) * 100 -> 2.5255218 | R4: =ABS(G4-sector_SC1_2_3_up!G18) * 100 -> 18.041165 | S4: =ABS(H4-sector_SC1_2_3_up!H18) * 100 -> 2.8327689 | T4: =ABS(I4-sector_SC1_2_3_up!I18) * 100 -> 2.7538177 | U4: =ABS(J4-sector_SC1_2_3_up!J18) * 100 -> 0.087775958
B5: Energy | C5: 4.9892566 | D5: 4.5499098 | E5: 4.0568467 | F5: 3.3577286 | G5: 2.284493 | H5: 1.0000683 | I5: 0 | J5: 0 | M5: Energy | N5: =ABS(C5-sector_SC1_2_3_up!C19) * 100 -> 0.074342362 | O5: =ABS(D5-sector_SC1_2_3_up!D19) * 100 -> 3.9909776 | P5: =ABS(E5-sector_SC1_2_3_up!E19) * 100 -> 9.6846702 | Q5: =ABS(F5-sector_SC1_2_3_up!F19) * 100 -> 2.7728592 | R5: =ABS(G5-sector_SC1_2_3_up!G19) * 100 -> 7.4493026 | S5: =ABS(H5-sector_SC1_2_3_up!H19) * 100 -> 5.0068334 | T5: =ABS(I5-sector_SC1_2_3_up!I19) * 100 -> 1 | U5: =ABS(J5-sector_SC1_2_3_up!J19) * 100 -> 0
B6: Financials | C6: 13.563798 | D6: 14.904583 | E6: 15.991483 | F6: 17.857459 | G6: 21.091487 | H6: 26.04491 | I6: 37.75263 | J6: 81.712333 | M6: Financials | N6: =ABS(C6-sector_SC1_2_3_up!C20) * 100 -> 0.37983011 | O6: =ABS(D6-sector_SC1_2_3_up!D20) * 100 -> 0.54174597 | P6: =ABS(E6-sector_SC1_2_3_up!E20) * 100 -> 3.8517423 | Q6: =ABS(F6-sector_SC1_2_3_up!F20) * 100 -> 2.2541391 | R6: =ABS(G6-sector_SC1_2_3_up!G20) * 100 -> 7.8513085 | S6: =ABS(H6-sector_SC1_2_3_up!H20) * 100 -> 1.4910086 | T6: =ABS(I6-sector_SC1_2_3_up!I20) * 100 -> 35.736993 | U6: =ABS(J6-sector_SC1_2_3_up!J20) * 100 -> 0.23327801
B7: Health Care | C7: 14.14539 | D7: 14.689786 | E7: 15.021247 | F7: 15.392841 | G7: 15.605785 | H7: 14.871623 | I7: 10.737014 | J7: 3.9804607 | M7: Health Care | N7: =ABS(C7-sector_SC1_2_3_up!C21) * 100 -> 0.46095849 | O7: =ABS(D7-sector_SC1_2_3_up!D21) * 100 -> 9.9785608 | P7: =ABS(E7-sector_SC1_2_3_up!E21) * 100 -> 22.124711 | Q7: =ABS(F7-sector_SC1_2_3_up!F21) * 100 -> 4.2841288 | R7: =ABS(G7-sector_SC1_2_3_up!G21) * 100 -> 21.57851 | S7: =ABS(H7-sector_SC1_2_3_up!H21) * 100 -> 7.1623193 | T7: =ABS(I7-sector_SC1_2_3_up!I21) * 100 -> 12.701448 | U7: =ABS(J7-sector_SC1_2_3_up!J21) * 100 -> 0.046068308
B8: Industrials | C8: 9.8960771 | D8: 9.9373587 | E8: 9.7550363 | F8: 9.0746723 | G8: 7.5494986 | H8: 6.2992165 | I8: 4.7398873 | J8: 2.8545656 | M8: Industrials | N8: =ABS(C8-sector_SC1_2_3_up!C22) * 100 -> 0.3922916 | O8: =ABS(D8-sector_SC1_2_3_up!D22) * 100 -> 5.2641328 | P8: =ABS(E8-sector_SC1_2_3_up!E22) * 100 -> 8.4963669 | Q8: =ABS(F8-sector_SC1_2_3_up!F22) * 100 -> 1.5327716 | R8: =ABS(G8-sector_SC1_2_3_up!G22) * 100 -> 18.050139 | S8: =ABS(H8-sector_SC1_2_3_up!H22) * 100 -> 8.0783463 | T8: =ABS(I8-sector_SC1_2_3_up!I22) * 100 -> 1.0112709 | U8: =ABS(J8-sector_SC1_2_3_up!J22) * 100 -> 0.54343834
B9: Information Technology | C9: 21.078442 | D9: 21.7345 | E9: 22.178478 | F9: 22.778819 | G9: 23.484681 | H9: 24.065815 | I9: 24.412305 | J9: 9.5532728 | M9: Information Technology | N9: =ABS(C9-sector_SC1_2_3_up!C23) * 100 -> 0.15579519 | O9: =ABS(D9-sector_SC1_2_3_up!D23) * 100 -> 0.44996509 | P9: =ABS(E9-sector_SC1_2_3_up!E23) * 100 -> 0.15220311 | Q9: =ABS(F9-sector_SC1_2_3_up!F23) * 100 -> 0.11806184 | R9: =ABS(G9-sector_SC1_2_3_up!G23) * 100 -> 0.46805845 | S9: =ABS(H9-sector_SC1_2_3_up!H23) * 100 -> 2.4184649 | T9: =ABS(I9-sector_SC1_2_3_up!I23) * 100 -> 6.2305413 | U9: =ABS(J9-sector_SC1_2_3_up!J23) * 100 -> 0.32727628
B10: Materials | C10: 4.2830313 | D10: 3.1561848 | E10: 2.4311939 | F10: 1.5838108 | G10: 0.85882011 | H10: 0.43020382 | I10: 0.21798076 | J10: 0.16667027 | M10: Materials | N10: =ABS(C10-sector_SC1_2_3_up!C24) * 100 -> 0.30312638 | O10: =ABS(D10-sector_SC1_2_3_up!D24) * 100 -> 6.3815188 | P10: =ABS(E10-sector_SC1_2_3_up!E24) * 100 -> 8.880606 | Q10: =ABS(F10-sector_SC1_2_3_up!F24) * 100 -> 3.6189176 | R10: =ABS(G10-sector_SC1_2_3_up!G24) * 100 -> 5.1179886 | S10: =ABS(H10-sector_SC1_2_3_up!H24) * 100 -> 0.9796184 | T10: =ABS(I10-sector_SC1_2_3_up!I24) * 100 -> 1.2019237 | U10: =ABS(J10-sector_SC1_2_3_up!J24) * 100 -> 0.3329726
B11: Real Estate | C11: 2.8970755 | D11: 3.2053439 | E11: 3.3926108 | F11: 3.5991852 | G11: 3.7976047 | H11: 3.826236 | I11: 3.0185765 | J11: 0.93562322 | M11: Real Estate | N11: =ABS(C11-sector_SC1_2_3_up!C25) * 100 -> 0.29244764 | O11: =ABS(D11-sector_SC1_2_3_up!D25) * 100 -> 3.4656071 | P11: =ABS(E11-sector_SC1_2_3_up!E25) * 100 -> 7.7389214 | Q11: =ABS(F11-sector_SC1_2_3_up!F25) * 100 -> 0.081479033 | R11: =ABS(G11-sector_SC1_2_3_up!G25) * 100 -> 4.2395327 | S11: =ABS(H11-sector_SC1_2_3_up!H25) * 100 -> 3.3763958 | T11: =ABS(I11-sector_SC1_2_3_up!I25) * 100 -> 2.1423519 | U11: =ABS(J11-sector_SC1_2_3_up!J25) * 100 -> 0.43767837
B12: Utilities | C12: 3.2076091 | D12: 1.6663045 | E12: 1.1241443 | F12: 0.70773064 | G12: 0.42583671 | H12: 0.40713159 | I12: 0.44683567 | J12: 0.37780224 | M12: Utilities | N12: =ABS(C12-sector_SC1_2_3_up!C26) * 100 -> 0.2390925 | O12: =ABS(D12-sector_SC1_2_3_up!D26) * 100 -> 0.36955172 | P12: =ABS(E12-sector_SC1_2_3_up!E26) * 100 -> 8.5855676 | Q12: =ABS(F12-sector_SC1_2_3_up!F26) * 100 -> 0.2269363 | R12: =ABS(G12-sector_SC1_2_3_up!G26) * 100 -> 6.4163287 | S12: =ABS(H12-sector_SC1_2_3_up!H26) * 100 -> 1.2868407 | T12: =ABS(I12-sector_SC1_2_3_up!I26) * 100 -> 1.3164335 | U12: =ABS(J12-sector_SC1_2_3_up!J26) * 100 -> 0.2197758
B15: Thierry | C15: 0 | D15: 30 | E15: 40 | F15: 50 | G15: 60 | H15: 70 | I15: 80 | J15: 90
B16: Communication Services | C16: 7.58 | D16: 7.96 | E16: 8.3 | F16: 8.8 | G16: 9.57 | H16: 10.46 | I16: 10.74 | J16: 0.18
B17: Consumer Discretionary | C17: 10.56 | D17: 10.8 | E17: 10.87 | F17: 10.71 | G17: 10.44 | H17: 9.49 | I17: 6.75 | J17: 0
B18: Consumer Staples | C18: 7.8 | D18: 7.37 | E18: 6.83 | F18: 6.14 | G18: 4.76 | H18: 3.09 | I18: 0.96 | J18: 0.24
B19: Energy | C19: 4.99 | D19: 4.51 | E19: 3.96 | F19: 3.33 | G19: 2.21 | H19: 0.95 | I19: 0.01 | J19: 0
B20: Financials | C20: 13.56 | D20: 14.91 | E20: 16.03 | F20: 17.88 | G20: 21.17 | H20: 26.03 | I20: 38.11 | J20: 81.71
B21: Health | C21: 14.15 | D21: 14.59 | E21: 14.8 | F21: 15.35 | G21: 15.39 | H21: 14.8 | I21: 10.61 | J21: 3.98
B22: Industrials | C22: 9.9 | D22: 9.99 | E22: 9.84 | F22: 9.09 | G22: 7.73 | H22: 6.38 | I22: 4.75 | J22: 2.86
B23: Information | C23: 21.08 | D23: 21.73 | E23: 22.18 | F23: 22.78 | G23: 23.48 | H23: 24.09 | I23: 24.35 | J23: 9.55
B24: Materials | C24: 4.28 | D24: 3.22 | E24: 2.52 | F24: 1.62 | G24: 0.91 | H24: 0.44 | I24: 0.23 | J24: 0.17
B25: Real | C25: 2.9 | D25: 3.24 | E25: 3.47 | F25: 3.6 | G25: 3.84 | H25: 3.86 | I25: 3.04 | J25: 0.94
B26: Utilities | C26: 3.21 | D26: 1.67 | E26: 1.21 | F26: 0.71 | G26: 0.49 | H26: 0.42 | I26: 0.46 | J26: 0.38

Sheet sector_SC1_2_3
A1: In % | B1: msci_gics_sector | C1: 0.0 | D1: 0.3 | E1: 0.4 | F1: 0.5 | G1: 0.6 | H1: 0.7 | I1: 0.8 | J1: 0.9 | L1: Diff (in bps) | M1: msci_gics_sector | N1: 0.0 | O1: 0.3 | P1: 0.4 | Q1: 0.5 | R1: 0.6 | S1: 0.7 | T1: 0.8 | U1: 0.9
B2: Communication Services | C2: 7.5792678 | D2: 7.9454177 | E2: 8.1546215 | F2: 8.4158318 | G2: 8.7752614 | H2: 9.3395217 | I2: 10.129529 | J2: 12.268734 | M2: Communication Services | N2: =ABS(C2-C16) *100 -> 0.073217565 | O2: =ABS(D2-D16) *100 -> 0.45823321 | P2: =ABS(E2-E16) *100 -> 1.4621482 | Q2: =ABS(F2-F16) *100 -> 2.5831766 | R2: =ABS(G2-G16) *100 -> 1.5261433 | S2: =ABS(H2-H16) *100 -> 0.95217047 | T2: =ABS(I2-I16) *100 -> 1.9528526 | U2: =ABS(J2-J16) *100 -> 3.1266185
B3: Consumer Discretionary | C3: 10.558518 | D3: 10.686018 | E3: 10.68888 | F3: 10.648566 | G3: 10.515893 | H3: 10.229283 | I3: 9.6157617 | J3: 6.7405769 | M3: Consumer Discretionary | N3: =ABS(C3-C17) *100 -> 0.14816911 | O3: =ABS(D3-D17) *100 -> 6.3981768 | P3: =ABS(E3-E17) *100 -> 5.1120084 | Q3: =ABS(F3-F17) *100 -> 10.143381 | R3: =ABS(G3-G17) *100 -> 3.410658 | S3: =ABS(H3-H17) *100 -> 2.0716514 | T3: =ABS(I3-I17) *100 -> 1.4238296 | U3: =ABS(J3-J17) *100 -> 2.0576869
B4: Consumer Staples | C4: 7.8015336 | D4: 7.8031438 | E4: 7.685833 | F4: 7.4783195 | G4: 7.1094718 | H4: 6.3469958 | I4: 5.0316748 | J4: 1.7669473 | M4: Consumer Staples | N4: =ABS(C4-C18) *100 -> 0.15335796 | O4: =ABS(D4-D18) *100 -> 13.314383 | P4: =ABS(E4-E18) *100 -> 8.5833002 | Q4: =ABS(F4-F18) *100 -> 17.831945 | R4: =ABS(G4-G18) *100 -> 4.9471844 | S4: =ABS(H4-H18) *100 -> 2.6995773 | T4: =ABS(I4-I18) *100 -> 3.1674826 | U4: =ABS(J4-J18) *100 -> 0.69473151
B5: Energy | C5: 4.9892566 | D5: 4.141651 | E5: 3.6518412 | F5: 3.0950726 | G5: 2.4462894 | H5: 1.5044371 | I5: 0.49222921 | J5: 0 | M5: Energy | N5: =ABS(C5-C19) *100 -> 0.074342362 | O5: =ABS(D5-D19) *100 -> 4.1651016 | P5: =ABS(E5-E19) *100 -> 4.184122 | Q5: =ABS(F5-F19) *100 -> 8.5072598 | R5: =ABS(G5-G19) *100 -> 2.6289387 | S5: =ABS(H5-H19) *100 -> 0.44370554 | T5: =ABS(I5-I19) *100 -> 0.22292053 | U5: =ABS(J5-J19) *100 -> 0
B6: Financials | C6: 13.563798 | D6: 14.533725 | E6: 15.170668 | F6: 15.935291 | G6: 16.897801 | H6: 18.394696 | I6: 20.55045 | J6: 28.61965 | M6: Financials | N6: =ABS(C6-C20) *100 -> 0.37983011 | O6: =ABS(D6-D20) *100 -> 1.3725494 | P6: =ABS(E6-E20) *100 -> 3.0668325 | Q6: =ABS(F6-F20) *100 -> 8.5291236 | R6: =ABS(G6-G20) *100 -> 0.78007249 | S6: =ABS(H6-H20) *100 -> 0.53035885 | T6: =ABS(I6-I20) *100 -> 3.9550387 | U6: =ABS(J6-J20) *100 -> 0.96495789
B7: Health Care | C7: 14.14539 | D7: 14.743239 | E7: 15.093356 | F7: 15.496468 | G7: 15.99706 | H7: 16.7752 | I7: 17.76526 | J7: 17.689959 | M7: Health Care | N7: =ABS(C7-C21) *100 -> 0.46095849 | O7: =ABS(D7-D21) *100 -> 15.32394 | P7: =ABS(E7-E21) *100 -> 11.335608 | Q7: =ABS(F7-F21) *100 -> 23.646766 | R7: =ABS(G7-G21) *100 -> 4.706047 | S7: =ABS(H7-H21) *100 -> 2.5200328 | T7: =ABS(I7-I21) *100 -> 6.5260431 | U7: =ABS(J7-J21) *100 -> 1.9958686
B8: Industrials | C8: 9.8960771 | D8: 9.2791101 | E8: 9.0096944 | F8: 8.7140577 | G8: 8.3608072 | H8: 7.7913483 | I8: 7.2099086 | J8: 6.0269068 | M8: Industrials | N8: =ABS(C8-C22) *100 -> 0.3922916 | O8: =ABS(D8-D22) *100 -> 11.088987 | P8: =ABS(E8-E22) *100 -> 9.0305554 | Q8: =ABS(F8-F22) *100 -> 24.594233 | R8: =ABS(G8-G22) *100 -> 5.9192825 | S8: =ABS(H8-H22) *100 -> 0.86516808 | T8: =ABS(I8-I22) *100 -> 0.0091434183 | U8: =ABS(J8-J22) *100 -> 0.69068279
B9: Information Technology | C9: 21.078442 | D9: 21.684106 | E9: 22.025641 | F9: 22.38772 | G9: 22.877895 | H9: 23.509946 | I9: 24.116615 | J9: 24.022226 | M9: Information Technology | N9: =ABS(C9-C23) *100 -> 0.15579519 | O9: =ABS(D9-D23) *100 -> 1.410572 | P9: =ABS(E9-E23) *100 -> 1.5641198 | Q9: =ABS(F9-F23) *100 -> 1.7720128 | R9: =ABS(G9-G23) *100 -> 0.78953421 | S9: =ABS(H9-H23) *100 -> 0.0053572752 | T9: =ABS(I9-I23) *100 -> 0.66148196 | U9: =ABS(J9-J23) *100 -> 4.7774388
B10: Materials | C10: 4.2830313 | D10: 3.7825571 | E10: 3.4641293 | F10: 3.0611191 | G10: 2.5564992 | H10: 1.8509415 | I10: 1.1445938 | J10: 0.24013962 | M10: Materials | N10: =ABS(C10-C24) *100 -> 0.30312638 | O10: =ABS(D10-D24) *100 -> 4.7442943 | P10: =ABS(E10-E24) *100 -> 4.5870701 | Q10: =ABS(F10-F24) *100 -> 8.888093 | R10: =ABS(G10-G24) *100 -> 1.3500847 | S10: =ABS(H10-H24) *100 -> 0.90584989 | T10: =ABS(I10-I24) *100 -> 3.5406239 | U10: =ABS(J10-J24) *100 -> 0.013962361
B11: Real Estate | C11: 2.8970755 | D11: 3.1229821 | E11: 3.2658558 | F11: 3.4118956 | G11: 3.5676532 | H11: 3.717061 | I11: 3.7056201 | J11: 2.5092581 | M11: Real Estate | N11: =ABS(C11-C25) *100 -> 0.29244764 | O11: =ABS(D11-D25) *100 -> 6.7017896 | P11: =ABS(E11-E25) *100 -> 3.4144225 | Q11: =ABS(F11-F25) *100 -> 7.8104364 | R11: =ABS(G11-G25) *100 -> 1.2346824 | S11: =ABS(H11-H25) *100 -> 0.2939012 | T11: =ABS(I11-I25) *100 -> 1.4379891 | U11: =ABS(J11-J25) *100 -> 1.9258117
B12: Utilities | C12: 3.2076091 | D12: 2.2780494 | E12: 1.7894793 | F12: 1.3556586 | G12: 0.89536787 | H12: 0.54056801 | I12: 0.23835844 | J12: 0.11560356 | M12: Utilities | N12: =ABS(C12-C26) *100 -> 0.2390925 | O12: =ABS(D12-D26) *100 -> 6.1950649 | P12: =ABS(E12-E26) *100 -> 7.0520743 | Q12: =ABS(F12-F26) *100 -> 10.434141 | R12: =ABS(G12-G26) *100 -> 3.4632127 | S12: =ABS(H12-H26) *100 -> 0.94319935 | T12: =ABS(I12-I26) *100 -> 2.1641561 | U12: =ABS(J12-J26) *100 -> 0.56035558
B15: Thierry | C15: 0 | D15: 30 | E15: 40 | F15: 50 | G15: 60 | H15: 70 | I15: 80 | J15: 90
B16: Communication Services | C16: 7.58 | D16: 7.95 | E16: 8.14 | F16: 8.39 | G16: 8.76 | H16: 9.33 | I16: 10.11 | J16: 12.3
B17: Consumer Discretionary | C17: 10.56 | D17: 10.75 | E17: 10.74 | F17: 10.75 | G17: 10.55 | H17: 10.25 | I17: 9.63 | J17: 6.72
B18: Consumer Staples | C18: 7.8 | D18: 7.67 | E18: 7.6 | F18: 7.3 | G18: 7.06 | H18: 6.32 | I18: 5 | J18: 1.76
B19: Energy | C19: 4.99 | D19: 4.1 | E19: 3.61 | F19: 3.01 | G19: 2.42 | H19: 1.5 | I19: 0.49 | J19: 0
B20: Financials | C20: 13.56 | D20: 14.52 | E20: 15.14 | F20: 15.85 | G20: 16.89 | H20: 18.4 | I20: 20.59 | J20: 28.61
B21: Health | C21: 14.15 | D21: 14.59 | E21: 14.98 | F21: 15.26 | G21: 15.95 | H21: 16.75 | I21: 17.7 | J21: 17.67
B22: Industrials | C22: 9.9 | D22: 9.39 | E22: 9.1 | F22: 8.96 | G22: 8.42 | H22: 7.8 | I22: 7.21 | J22: 6.02
B23: Information | C23: 21.08 | D23: 21.67 | E23: 22.01 | F23: 22.37 | G23: 22.87 | H23: 23.51 | I23: 24.11 | J23: 24.07
B24: Materials | C24: 4.28 | D24: 3.83 | E24: 3.51 | F24: 3.15 | G24: 2.57 | H24: 1.86 | I24: 1.18 | J24: 0.24
B25: Real | C25: 2.9 | D25: 3.19 | E25: 3.3 | F25: 3.49 | G25: 3.58 | H25: 3.72 | I25: 3.72 | J25: 2.49
B26: Utilities | C26: 3.21 | D26: 2.34 | E26: 1.86 | F26: 1.46 | G26: 0.93 | H26: 0.55 | I26: 0.26 | J26: 0.11
B27: Total

Sheet GRS intensit
A1: GRS (in %) | B1: Index/Reduction | C1: 0.3 | D1: 0.4 | E1: 0.5 | F1: 0.6 | G1: 0.7 | H1: 0.8 | I1: 0.9 | K1: Diff (in bps) | L1: 0.3 | M1: 0.4 | N1: 0.5 | O1: 0.6 | P1: 0.7 | Q1: 0.8 | R1: 0.9
A2: SC1 | B2: 5.244946 | C2: 5.2066702 | D2: 5.1913417 | E2: 5.1831127 | F2: 5.1606585 | G2: 5.1182049 | H2: 5.0774427 | I2: 5.0054483 | K2: SC1 | L2: =ABS(C2-C8) -> 0.1233298 | M2: =ABS(D2-D8) * 100 -> 3.8658307 | N2: =ABS(E2-E8) * 100 -> 7.6887324 | O2: =ABS(F2-F8) * 100 -> 6.9341472 | P2: =ABS(G2-G8) * 100 -> 1.1795081 | Q2: =ABS(H2-H8) * 100 -> 7.2557326 | R2: =ABS(I2-I8) * 100 -> 2.4551749
A3: SC1_2 | B3: 5.244946 | C3: 5.171315 | D3: 5.1357164 | E3: 5.0866404 | F3: 4.993779 | G3: 4.8290657 | H3: 4.6444503 | I3: 4.5154557 | K3: SC1_2 | L3: =ABS(C3-C9) -> 0.15868504 | M3: =ABS(D3-D9) * 100 -> 9.4283623 | N3: =ABS(E3-E9) * 100 -> 14.335958 | O3: =ABS(F3-F9) * 100 -> 1.6220954 | P3: =ABS(G3-G9) * 100 -> 7.0934311 | Q3: =ABS(H3-H9) * 100 -> 2.5549726 | R3: =ABS(I3-I9) * 100 -> 1.4544254
A4: SC_1_2_3 | B4: 5.244946 | C4: 5.1483705 | D4: 5.068552 | E4: 4.8943492 | F4: 4.6856602 | G4: 4.417712 | H4: 3.8995995 | I4: 0.67800044 | K4: SC_1_2_3 | L4: =ABS(C4-C10) -> 0.031629513 | M4: =ABS(D4-D10) * 100 -> 8.1447982 | N4: =ABS(E4-E10) * 100 -> 1.5650785 | O4: =ABS(F4-F10) * 100 -> 7.4339752 | P4: =ABS(G4-G10) * 100 -> 4.228801 | Q4: =ABS(H4-H10) * 100 -> 1.040047 | R4: =ABS(I4-I10) * 100 -> 0.19995559
A5: SC_1_2_3_up | B5: 5.244946 | C5: 5.1740361 | D5: 5.1192506 | E5: 5.0464915 | F5: 4.9660614 | G5: 4.8019615 | H5: 4.5494856 | I5: 3.7346232 | K5: SC_1_2_3_up | L5: =ABS(C5-C11) -> 0.065963929 | M5: =ABS(D5-D11) * 100 -> 4.0749423 | N5: =ABS(E5-E11) * 100 -> 10.350847 | O5: =ABS(F5-F11) * 100 -> 1.3938641 | P5: =ABS(G5-G11) * 100 -> 0.80385219 | Q5: =ABS(H5-H11) * 100 -> 2.0514424 | R5: =ABS(I5-I11) * 100 -> 0.53768
A7: Thierry | B7: 0 | C7: 30 | D7: 40 | E7: 50 | F7: 60 | G7: 70 | H7: 80 | I7: 90
A8: SC1 | B8: 5.24 | C8: 5.33 | D8: 5.23 | E8: 5.26 | F8: 5.23 | G8: 5.13 | H8: 5.15 | I8: 5.03
A9: SC1_2 | B9: 5.24 | C9: 5.33 | D9: 5.23 | E9: 5.23 | F9: 5.01 | G9: 4.9 | H9: 4.67 | I9: 4.53
A10: SC_1_2_3 | B10: 5.24 | C10: 5.18 | D10: 5.15 | E10: 4.91 | F10: 4.76 | G10: 4.46 | H10: 3.91 | I10: 0.68
A11: SC_1_2_3_up | B11: 5.24 | C11: 5.24 | D11: 5.16 | E11: 5.15 | F11: 4.98 | G11: 4.81 | H11: 4.57 | I11: 3.74
A14: Dropping Nas (Noureddine) | B14: Index/Reduction | C14: 0.3 | D14: 0.4 | E14: 0.5 | F14: 0.6 | G14: 0.7 | H14: 0.8 | I14: 0.9 | K14: Diff (in bps) | L14: 0.3 | M14: 0.4 | N14: 0.5 | O14: 0.6 | P14: 0.7 | Q14: 0.8 | R14: 0.9
A15: SC1 | B15: 5.268342 | C15: 5.227555 | D15: 5.210458 | E15: 5.199417 | F15: 5.17623 | G15: 5.133867 | H15: 5.093316 | I15: 5.021327 | K15: SC1 | L15: =ABS(B15-B2) -> 0.023395951 | M15: =ABS(C15-C2) -> 0.0208848 | N15: =ABS(D15-D2) -> 0.019116307 | O15: =ABS(E15-E2) -> 0.016304324 | P15: =ABS(F15-F2) -> 0.015571472 | Q15: =ABS(G15-G2) -> 0.015662081 | R15: =ABS(H15-H2) -> 0.015873326
A16: SC1_2 | B16: 5.268342 | C16: 5.191615 | D16: 5.153691 | E16: 5.10204 | F16: 5.00915 | G16: 4.844336 | H16: 4.659777 | I16: 4.530593 | K16: SC1_2 | L16: =ABS(B16-B3) -> 0.023395951 | M16: =ABS(C16-C3) -> 0.020300041 | N16: =ABS(D16-D3) -> 0.017974623 | O16: =ABS(E16-E3) -> 0.015399582 | P16: =ABS(F16-F3) -> 0.015370954 | Q16: =ABS(G16-G3) -> 0.015270311 | R16: =ABS(H16-H3) -> 0.015326726
A17: SC_1_2_3 | B17: 5.268342 | C17: 5.16629 | D17: 5.084484 | E17: 4.910462 | F17: 4.702063 | G17: 4.43394 | H17: 3.911943 | I17: 0.678315 | K17: SC_1_2_3 | L17: =ABS(B17-B4) -> 0.023395951 | M17: =ABS(C17-C4) -> 0.017919513 | N17: =ABS(D17-D4) -> 0.015931982 | O17: =ABS(E17-E4) -> 0.016112785 | P17: =ABS(F17-F4) -> 0.016402752 | Q17: =ABS(G17-G4) -> 0.01622801 | R17: =ABS(H17-H4) -> 0.01234347
A18: SC_1_2_3_up | B18: 5.268342 | C18: 5.195981 | D18: 5.139799 | E18: 5.064874 | F18: 4.981735 | G18: 4.817289 | H18: 4.563589 | I18: 3.736907 | K18: SC_1_2_3_up | L18: =ABS(B18-B5) -> 0.023395951 | M18: =ABS(C18-C5) -> 0.021944929 | N18: =ABS(D18-D5) -> 0.020548423 | O18: =ABS(E18-E5) -> 0.018382466 | P18: =ABS(F18-F5) -> 0.015673641 | Q18: =ABS(G18-G5) -> 0.015327522 | R18: =ABS(H18-H5) -> 0.014103424

Sheet CTB
A1: CTB_C0 | B1: reduction | C1: SC1 | D1: SC1_2 | E1: SC1_2_3_up | F1: SC1_2_3 | G1: year | I1: CTB_C3_0_2_1 | J1: reduction | K1: SC1 | L1: SC1_2 | M1: SC1_2_3_up | N1: SC1_2_3 | O1: year
B2: 0 | C2: 0 | D2: 0 | E2: 0 | F2: 0 | G2: 2020 | J2: 0 | K2: 0 | L2: 0 | M2: 0 | N2: 0 | O2: 2020
A3: 0 | B3: 0.3 | C3: 5.3502279 | D3: 6.5503079 | E3: 11.205299 | F3: 11.221081 | G3: 2021 | I3: 0 | J3: 0.3 | K3: 7.0114718 | L3: 8.7515268 | M3: 16.663742 | N3: 14.406641 | O3: 2021
A4: 1 | B4: 0.349 | C4: 6.4355195 | D4: 7.9223081 | E4: 14.068947 | F4: 13.923704 | G4: 2022 | I4: 1 | J4: 0.349 | K4: 8.6203447 | L4: 10.819083 | M4: 22.464812 | N4: 18.432881 | O4: 2022
A5: 2 | B5: 0.39457 | C5: 7.5318818 | D5: 9.3186561 | E5: 17.155945 | F5: 16.66984 | G5: 2023 | I5: 2 | J5: 0.39457 | K5: 10.300114 | L5: 13.018607 | M5: 30.581706 | N5: 22.692553 | O5: 2023
A6: 3 | B6: 0.4369501 | C6: 8.6385152 | D6: 10.736286 | E6: 20.462525 | F6: 19.425797 | G6: 2024 | I6: 3 | J6: 0.4369501 | K6: 12.040692 | L6: 15.340359 | M6: 42.350269 | N6: 27.201705 | O6: 2024
A7: 4 | B7: 0.47636359 | C7: 9.7628511 | D7: 12.162611 | E7: 24.024935 | F7: 22.183492 | G7: 2025 | I7: 4 | J7: 0.47636359 | K7: 13.859814 | L7: 17.912778 | M7: 60.71449 | N7: 32.422049 | O7: 2025
A8: 5 | B8: 0.51301814 | C8: 10.884627 | D8: 13.609065 | E8: 27.901352 | F8: 24.923945 | G8: 2026 | I8: 5 | J8: 0.51301814 | K8: 15.906132 | L8: 20.843285 | M8: 123.33378 | N8: 38.690335 | O8: 2026
A9: 6 | B9: 0.54710687 | C9: 11.994648 | D9: 15.093602 | E9: 32.158145 | F9: 27.657604 | G9: 2027 | I9: 6 | J9: 0.54710687 | K9: 18.255469 | L9: 24.44803 | N9: 46.335817 | O9: 2027
A10: 7 | B10: 0.57880939 | C10: 13.130682 | D10: 16.604143 | E10: 36.681296 | F10: 30.353759 | G10: 2028 | I10: 7 | J10: 0.57880939 | K10: 20.953314 | L10: 29.301065 | N10: 56.768516 | O10: 2028
A11: 8 | B11: 0.60829273 | C11: 14.293405 | D11: 18.156889 | E11: 41.439342 | F11: 33.022391 | G11: 2029 | I11: 8 | J11: 0.60829273 | K11: 24.078527 | L11: 36.481326 | N11: 72.270194 | O11: 2029
A12: 9 | B12: 0.63571224 | C12: 15.489135 | D12: 19.75986 | E12: 46.447125 | F12: 35.724256 | G12: 2030 | I12: 9 | J12: 0.63571224 | K12: 27.976081 | L12: 48.108327 | N12: 128.51401 | O12: 2030
A13: 10 | B13: 0.66121238 | C13: 16.738289 | D13: 21.421444 | E13: 51.626129 | F13: 38.463803 | G13: 2031 | I13: 10 | J13: 0.66121238 | K13: 33.593568 | L13: 83.73662 | O13: 2031
A14: 11 | B14: 0.68492752 | C14: 18.01891 | D14: 23.221512 | E14: 56.990142 | F14: 41.223678 | G14: 2032 | I14: 11 | J14: 0.68492752 | K14: 42.072259 | O14: 2032
A15: 12 | B15: 0.70698259 | C15: 19.321251 | D15: 25.168138 | E15: 62.475233 | F15: 44.003365 | G15: 2033 | I15: 12 | J15: 0.70698259 | K15: 62.979614 | O15: 2033
A16: 13 | B16: 0.72749381 | C16: 20.689362 | D16: 27.22535 | E16: 67.993941 | F16: 46.786742 | G16: 2034 | I16: 13 | J16: 0.72749381 | O16: 2034
A17: 14 | B17: 0.74656924 | C17: 22.119816 | D17: 29.385738 | E17: 73.534736 | F17: 49.560947 | G17: 2035 | I17: 14 | J17: 0.74656924 | O17: 2035
A18: 15 | B18: 0.7643094 | C18: 23.604434 | D18: 31.660958 | E18: 79.173824 | F18: 52.301596 | G18: 2036 | I18: 15 | J18: 0.7643094 | O18: 2036
A19: 16 | B19: 0.78080774 | C19: 25.123136 | D19: 34.06076 | E19: 85.34906 | F19: 55.005011 | G19: 2037 | I19: 16 | J19: 0.78080774 | O19: 2037
A20: 17 | B20: 0.7961512 | C20: 26.692965 | D20: 36.605321 | E20: 92.452347 | F20: 57.763812 | G20: 2038 | I20: 17 | J20: 0.7961512 | O20: 2038
A21: 18 | B21: 0.81042061 | C21: 28.308041 | D21: 39.261656 | E21: 100.59922 | F21: 60.666116 | G21: 2039 | I21: 18 | J21: 0.81042061 | O21: 2039
A22: 19 | B22: 0.82369117 | C22: 29.971445 | D22: 41.990505 | E22: 110.0174 | F22: 63.732377 | G22: 2040 | I22: 19 | J22: 0.82369117 | O22: 2040
A23: 20 | B23: 0.83603279 | C23: 31.68527 | D23: 44.775339 | E23: 120.83173 | F23: 66.902047 | G23: 2041 | I23: 20 | J23: 0.83603279 | O23: 2041
A24: 21 | B24: 0.84751049 | C24: 33.431217 | D24: 47.61027 | E24: 132.86295 | F24: 70.142939 | G24: 2042 | I24: 21 | J24: 0.84751049 | O24: 2042
A25: 22 | B25: 0.85818476 | C25: 35.1832 | D25: 50.454663 | E25: 146.21043 | F25: 73.50565 | G25: 2043 | I25: 22 | J25: 0.85818476 | O25: 2043
A26: 23 | B26: 0.86811183 | C26: 36.92755 | D26: 53.288912 | E26: 161.54557 | F26: 77.10391 | G26: 2044 | I26: 23 | J26: 0.86811183 | O26: 2044
A27: 24 | B27: 0.877344 | C27: 38.645427 | D27: 56.085326 | E27: 179.95654 | F27: 81.042419 | G27: 2045 | I27: 24 | J27: 0.877344 | O27: 2045
... A32: 29 | B32: 0.91466965 | C32: 46.84251 | D32: 71.118893 | E32: 332.69582 | F32: 110.12061 | G32: 2050 | I32: 29 | J32: 0.91466965 | O32: 2050

Sheet PAB
A1: PAB_C0 | B1: reduction | C1: SC1 | D1: SC1_2 | E1: SC1_2_3_up | F1: SC1_2_3 | G1: year | I1: PAB_C3_0_2_1 | J1: reduction | K1: SC1 | L1: SC1_2 | M1: SC1_2_3_up | N1: SC1_2_3 | O1: year
B2: 0 | C2: 0 | D2: 0 | E2: 0 | F2: 0 | G2: 2020 | J2: 0 | K2: 0 | L2: 0 | M2: 0 | N2: 0 | O2: 2020
A3: 0 | B3: 0.5 | C3: =[1]SC1!C2*10000 -> 10.478735 | D3: =[1]SC1!D2*10000 -> 13.076833 | E3: =[1]SC1!E2*10000 -> 26.44357 | F3: =[1]SC1!F2*10000 -> 23.930206 | G3: 2021 | I3: 0 | J3: 0.5 | K3: =[2]SC1!C2* 10000 -> 15.131247 | L3: =[2]SC1!D2* 10000 -> 19.719597 | M3: =[2]SC1!E2* 10000 -> 84.960064 | N3: =[2]SC1!F2* 10000 -> 36.267996 | O3: 2021
A4: 1 | B4: 0.535 | C4: =[1]SC1!C3*10000 -> 11.588791 | D4: =[1]SC1!D3*10000 -> 14.551353 | E4: =[1]SC1!E3*10000 -> 30.575271 | F4: =[1]SC1!F3*10000 -> 26.665368 | G4: 2022 | I4: 1 | J4: 0.535 | K4: =[2]SC1!C3* 10000 -> 17.359295 | L4: =[2]SC1!D3* 10000 -> 23.038196 | N4: =[2]SC1!F3* 10000 -> 43.359438 | O4: 2022
A5: 2 | B5: 0.56755 | C5: =[1]SC1!C4*10000 -> 12.714879 | D5: =[1]SC1!D4*10000 -> 16.052077 | E5: =[1]SC1!E4*10000 -> 35.010549 | F5: =[1]SC1!F4*10000 -> 29.380789 | G5: 2023 | I5: 2 | J5: 0.56755 | K5: =[2]SC1!C4* 10000 -> 19.934094 | L5: =[2]SC1!D4* 10000 -> 27.310508 | N5: =[2]SC1!F4* 10000 -> 52.498406 | O5: 2023
A6: 3 | B6: 0.5978215 | C6: =[1]SC1!C5*10000 -> 13.866742 | D6: =[1]SC1!D5*10000 -> 17.584695 | E6: =[1]SC1!E5*10000 -> 39.67971 | F6: =[1]SC1!F5*10000 -> 32.04977 | G6: 2024 | I6: 3 | J6: 0.5978215 | K6: =[2]SC1!C5* 10000 -> 22.875513 | L6: =[2]SC1!D5* 10000 -> 33.575624 | N6: =[2]SC1!F5* 10000 -> 65.853583 | O6: 2024
A7: 4 | B7: 0.625974 | C7: =[1]SC1!C6*10000 -> 15.048591 | D7: =[1]SC1!D6*10000 -> 19.173306 | E7: =[1]SC1!E6*10000 -> 44.604871 | F7: =[1]SC1!F6*10000 -> 34.7384 | G7: 2025 | I7: 4 | J7: 0.625974 | K7: =[2]SC1!C6* 10000 -> 26.418067 | L7: =[2]SC1!D6* 10000 -> 42.826094 | N7: =[2]SC1!F6* 10000 -> 91.120777 | O7: 2025
A8: 5 | B8: 0.65215582 | C8: =[1]SC1!C7*10000 -> 16.279289 | D8: =[1]SC1!D7*10000 -> 20.806178 | E8: =[1]SC1!E7*10000 -> 49.723616 | F8: =[1]SC1!F7*10000 -> 37.464007 | G8: 2026 | I8: 5 | J8: 0.65215582 | K8: =[2]SC1!C7* 10000 -> 31.303645 | L8: =[2]SC1!D7* 10000 -> 64.03321 | O8: 2026
A9: 6 | B9: 0.67650491 | C9: =[1]SC1!C8*10000 -> 17.55148 | D9: =[1]SC1!D8*10000 -> 22.549455 | E9: =[1]SC1!E8*10000 -> 55.020573 | F9: =[1]SC1!F8*10000 -> 40.218863 | G9: 2027 | I9: 6 | J9: 0.67650491 | K9: =[2]SC1!C8* 10000 -> 38.47659 | O9: 2027
A10: 7 | B10: 0.69914956 | C10: =[1]SC1!C9*10000 -> 18.840447 | D10: =[1]SC1!D9*10000 -> 24.445658 | E10: =[1]SC1!E9*10000 -> 60.473628 | F10: =[1]SC1!F9*10000 -> 42.991966 | G10: 2028 | I10: 7 | J10: 0.69914956 | K10: =[2]SC1!C9* 10000 -> 52.49996 | O10: 2028
A11: 8 | B11: 0.7202091 | C11: =[1]SC1!C10*10000 -> 20.184958 | D11: =[1]SC1!D10*10000 -> 26.46458 | E11: =[1]SC1!E10*10000 -> 65.98488 | F11: =[1]SC1!F10*10000 -> 45.775037 | G11: 2029 | I11: 8 | J11: 0.7202091 | O11: 2029
A12: 9 | B12: 0.73979446 | C12: =[1]SC1!C11*10000 -> 21.592682 | D12: =[1]SC1!D11*10000 -> 28.589362 | E12: =[1]SC1!E11*10000 -> 71.519019 | F12: =[1]SC1!F11*10000 -> 48.554942 | G12: 2030 | I12: 9 | J12: 0.73979446 | O12: 2030
A13: 10 | B13: 0.75800885 | C13: =[1]SC1!C12*10000 -> 23.060173 | D13: =[1]SC1!D12*10000 -> 30.819612 | E13: =[1]SC1!E12*10000 -> 77.099429 | F13: =[1]SC1!F12*10000 -> 51.309866 | G13: 2031 | I13: 10 | J13: 0.75800885 | O13: 2031
A14: 11 | B14: 0.77494823 | C14: =[1]SC1!C13*10000 -> 24.565684 | D14: =[1]SC1!D13*10000 -> 33.170935 | E14: =[1]SC1!E13*10000 -> 83.005895 | F14: =[1]SC1!F13*10000 -> 54.023179 | G14: 2032 | I14: 11 | J14: 0.77494823 | O14: 2032
A15: 12 | B15: 0.79070185 | C15: =[1]SC1!C14*10000 -> 26.117288 | D15: =[1]SC1!D14*10000 -> 35.665631 | E15: =[1]SC1!E14*10000 -> 89.759884 | F15: =[1]SC1!F14*10000 -> 56.752009 | G15: 2033 | I15: 12 | J15: 0.79070185 | O15: 2033
A16: 13 | B16: 0.80535272 | C16: =[1]SC1!C15*10000 -> 27.714687 | D16: =[1]SC1!D15*10000 -> 38.286187 | E16: =[1]SC1!E15*10000 -> 97.49743 | F16: =[1]SC1!F15*10000 -> 59.587992 | G16: 2034 | I16: 13 | J16: 0.80535272 | O16: 2034
A17: 14 | B17: 0.81897803 | C17: =[1]SC1!C16*10000 -> 29.361988 | D17: =[1]SC1!D16*10000 -> 40.991886 | E17: =[1]SC1!E16*10000 -> 106.43274 | F17: =[1]SC1!F16*10000 -> 62.602673 | G17: 2035 | I17: 14 | J17: 0.81897803 | O17: 2035
A18: 15 | B18: 0.83164957 | C18: =[1]SC1!C17*10000 -> 31.056855 | D18: =[1]SC1!D17*10000 -> 43.755661 | E18: =[1]SC1!E17*10000 -> 116.75178 | F18: =[1]SC1!F17*10000 -> 65.740407 | G18: 2036 | I18: 15 | J18: 0.83164957 | O18: 2036
A19: 16 | B19: 0.8434341 | C19: =[1]SC1!C18*10000 -> 32.794916 | D19: =[1]SC1!D18*10000 -> 46.576689 | E19: =[1]SC1!E18*10000 -> 128.35554 | F19: =[1]SC1!F18*10000 -> 68.957559 | G19: 2037 | I19: 16 | J19: 0.8434341 | O19: 2037
A20: 17 | B20: 0.85439371 | C20: =[1]SC1!C19*10000 -> 34.546497 | D20: =[1]SC1!D19*10000 -> 49.421925 | E20: =[1]SC1!E19*10000 -> 141.18884 | F20: =[1]SC1!F19*10000 -> 72.255611 | G20: 2038 | I20: 17 | J20: 0.85439371 | O20: 2038
A21: 18 | B21: 0.86458615 | C21: =[1]SC1!C20*10000 -> 36.295544 | D21: =[1]SC1!D20*10000 -> 52.260964 | E21: =[1]SC1!E20*10000 -> 155.65411 | F21: =[1]SC1!F20*10000 -> 75.766303 | G21: 2039 | I21: 18 | J21: 0.86458615 | O21: 2039
A22: 19 | B22: 0.87406512 | C22: =[1]SC1!C21*10000 -> 38.025088 | D22: =[1]SC1!D21*10000 -> 55.075215 | E22: =[1]SC1!E21*10000 -> 172.915 | F22: =[1]SC1!F21*10000 -> 79.562774 | G22: 2040 | I22: 19 | J22: 0.87406512 | O22: 2040
... A29: 26 | B29: 0.92422487 | C29: =[1]SC1!C28*10000 -> 49.325195 | D29: =[1]SC1!D28*10000 -> 77.707976 | E29: =[1]SC1!E28*10000 -> 1048.1103 | F29: =[1]SC1!F28*10000 -> 123.82718 | G29: 2047 | I29: 26 | J29: 0.92422487 | O29: 2047
A30: 27 | B30: 0.92952913 | C30: =[1]SC1!C29*10000 -> 50.772548 | D30: =[1]SC1!D29*10000 -> 82.179894 | F30: =[1]SC1!F29*10000 -> 133.42586 | G30: 2048 | I30: 27 | J30: 0.92952913 | O30: 2048
A31: 28 | B31: 0.93446209 | C31: =[1]SC1!C30*10000 -> 52.174612 | D31: =[1]SC1!D30*10000 -> 87.000444 | F31: =[1]SC1!F30*10000 -> 144.2543 | G31: 2049 | I31: 28 | J31: 0.93446209 | O31: 2049
A32: 29 | B32: 0.93904975 | C32: =[1]SC1!C31*10000 -> 53.550083 | D32: =[1]SC1!D31*10000 -> 92.261637 | F32: =[1]SC1!F31*10000 -> 156.52537 | G32: 2050 | I32: 29 | J32: 0.93904975 | O32: 2050

Sheet TE GRS C0
A1: Additionnal TE (in bps), G=0 | B1: 2022 | C1: 2023 | D1: 2024 | E1: 2025 | F1: 2030 | G1: 2035 | H1: 2040 | I1: 2045 | J1: 2050
A2: SC1 | B2: 0.01144804 | C2: 0.012547135 | D2: 0.013752463 | E2: 0.01509368 | F2: 0.019641545 | G2: 0.02657374 | H2: 0.029645587 | I2: 0.033453896 | J2: 0.039543938
A3: SC1_2 | B3: 0.05144548 | C3: 0.060566589 | D3: 0.074096001 | E3: 0.090481083 | F3: 0.20539566 | G3: 0.30836805 | H3: 0.31285129 | I3: 0.42292924 | J3: 0.95847137
A4: SC1_2_3_up | B4: 0.13296189 | C4: 0.15922922 | D4: 0.19317686 | E4: 0.22821563 | F4: 0.43156017 | G4: 1.7007528 | H4: 8.1774029 | I4: 56.051132
A5: SC1_2_3 | B5: 0.039302373 | C5: 0.043959883 | D5: 0.050910119 | E5: 0.059881207 | F5: 0.12779737 | G5: 0.26102772 | H5: 0.63749478 | I5: 2.193198 | J5: 7.1449806
A8: Additionnal TE (in bps), G=1 | B8: 2022 | C8: 2023 | D8: 2024 | E8: 2025 | F8: 2030 | G8: 2035 | H8: 2040 | I8: 2045 | J8: 2050
A9: SC1 | B9: 21.385271 | C9: 20.760211 | D9: 20.174742 | E9: 19.629309 | F9: 16.97663 | G9: 14.604874 | H9: 12.680542 | I9: 11.368776 | J9: 10.567761
A10: SC1_2 | B10: 20.484712 | C10: 19.948034 | D10: 19.495765 | E10: 19.080668 | F10: 17.669872 | G10: 16.595757 | H10: 15.796832 | I10: 17.553709 | J10: 20.452299
A11: SC1_2_3_up | B11: 16.046481 | C11: 15.453875 | D11: 15.017861 | E11: 14.655062 | F11: 13.685929 | G11: 21.114252 | H11: 48.300679 | I11: 220.16791
A12: SC1_2_3 | B12: 15.308839 | C12: 14.599594 | D12: 14.028538 | E12: 13.547558 | F12: 11.978445 | G12: 11.773367 | H12: 14.395896 | I12: 24.100283 | J12: 51.540642
A15: Additionnal TE (in bps), G=1, Fillna(0) | B15: 2022 | C15: 2023 | D15: 2024 | E15: 2025 | F15: 2030 | G15: 2035 | H15: 2040 | I15: 2045 | J15: 2050
A16: reduction | B16: 0 | C16: 0 | D16: 0 | E16: 0 | F16: 0 | G16: 0 | H16: 0 | I16: 0 | J16: 0
A17: SC1 | B17: 21.145364 | C17: 20.523007 | D17: 19.94015 | E17: 19.397573 | F17: 16.760808 | G17: 14.407906 | H17: 12.503806 | I17: 11.207126 | J17: 10.416043
A18: SC1_2 | B18: 20.249042 | C18: 19.715048 | D18: 19.26546 | E18: 18.853336 | F18: 17.453312 | G18: 16.391682 | H18: 15.602343 | I18: 17.333717 | J18: 20.206005
A19: SC1_2_3_up | B19: 15.84296 | C19: 15.256722 | D19: 14.826689 | E19: 14.468876 | F19: 13.514343 | G19: 20.88446 | H19: 47.867923 | I19: 218.19988
A20: SC1_2_3 | B20: 15.123023 | C20: 14.408138 | D20: 13.840274 | E20: 13.364333 | F20: 11.8164 | G20: 11.618897 | H20: 14.217492 | I20: 23.837968 | J20: 51.019986

Sheet C3(0,10,2)
A1: reduction | B1: SC1 | C1: SC1_2 | D1: SC1_2_3up | E1: SC1_2_3
A2: 0 | B2: 7.8350819e-11 | C2: 7.8350819e-11 | D2: 7.8350819e-11 | E2: 7.8350819e-11
A3: 0.01 | B3: 0.14259987 | C3: 0.17562552 | D3: 0.21700858 | E3: 0.29844834
A4: 0.02 | B4: 0.30223134 | C4: 0.3698516 | D4: 0.45345158 | E4: 0.59803163
A5: 0.03 | B5: 0.46580589 | C5: 0.56716618 | D5: 0.70268108 | E5: 0.90039804
A6: 0.04 | B6: 0.63026086 | C6: 0.76518373 | D6: 0.95488227 | E6: 1.2047614
A7: 0.05 | B7: 0.7950501 | C7: 0.96347091 | D7: 1.2144755 | E7: 1.5099222
A8: 0.06 | B8: 0.96000148 | C8: 1.1618897 | D8: 1.4963876 | E8: 1.8172576
A9: 0.07 | B9: 1.1250437 | C9: 1.3603825 | D9: 1.791733 | E9: 2.1271472
A10: 0.08 | B10: 1.2901419 | C10: 1.559981 | D10: 2.0978515 | E10: 2.4386176
A11: 0.09 | B11: 1.4560309 | C11: 1.7619518 | D11: 2.4119863 | E11: 2.7511329
A12: 0.1 | B12: 1.6239268 | C12: 1.965591 | D12: 2.7367612 | E12: 3.0658347
A13: 0.11 | B13: 1.793311 | C13: 2.1706664 | D13: 3.0714223 | E13: 3.3898033
... A71: 0.85439371 | B71: 36.312412 | C71: 58.014893 | D71: 308.61416 | E71: 89.906129
A72: 0.85818476 | B72: 37.111769 | C72: 59.732027 | E72: 92.111291
A73: 0.86458615 | B73: 38.533105 | C73: 62.794167 | E73: 96.323071
A74: 0.86811183 | B74: 39.354973 | C74: 64.568306 | E74: 98.964107
